Workbook
Name All_Teams: OFFSET(Games!#REF!,0,0,COUNTA(Games!#REF!)-1,1)
Name Method: Games!#REF!
Name SeedInfo: Games!#REF!
Name SeedType: Games!#REF!
Name snowball: [1]Calculator!$F$21
Name strategy: [1]Calculator!$F$20
Name valuevx: 42.314159

Sheet Team_Links
A1: Column1 | B1: School | C1: Link | D1: GameLogs | E1: PartialLink
A2: 0 | B2: Abilene Christian | C2: https://www.sports-reference.com/cbb/schools/abilene-christian/men/2026.html | D2: https://www.sports-reference.com/cbb/schools/abilene-christian/men/2026-gamelogs.html | E2: {=_xlfn.TEXTSPLIT( _xlfn.TEXTSPLIT(Team_Links[[#This Row],[GameLogs]],"https://www.sports-reference.com/cbb/schools/",,TRUE,0,), "/",,TRUE,0)} -> abilene-christian
A3: 1 | B3: Air Force | C3: https://www.sports-reference.com/cbb/schools/air-force/men/2026.html | D3: https://www.sports-reference.com/cbb/schools/air-force/men/2026-gamelogs.html | E3: {=_xlfn.TEXTSPLIT( _xlfn.TEXTSPLIT(Team_Links[[#This Row],[GameLogs]],"https://www.sports-reference.com/cbb/schools/",,TRUE,0,), "/",,TRUE,0)} -> air-force
A4: 2 | B4: Akron | C4: https://www.sports-reference.com/cbb/schools/akron/men/2026.html | D4: https://www.sports-reference.com/cbb/schools/akron/men/2026-gamelogs.html | E4: {=_xlfn.TEXTSPLIT( _xlfn.TEXTSPLIT(Team_Links[[#This Row],[GameLogs]],"https://www.sports-reference.com/cbb/schools/",,TRUE,0,), "/",,TRUE,0)} -> akron
A5: 3 | B5: Alabama | C5: https://www.sports-reference.com/cbb/schools/alabama/men/2026.html | D5: https://www.sports-reference.com/cbb/schools/alabama/men/2026-gamelogs.html | E5: {=_xlfn.TEXTSPLIT( _xlfn.TEXTSPLIT(Team_Links[[#This Row],[GameLogs]],"https://www.sports-reference.com/cbb/schools/",,TRUE,0,), "/",,TRUE,0)} -> alabama
A6: 4 | B6: Alabama A&M | C6: https://www.sports-reference.com/cbb/schools/alabama-am/men/2026.html | D6: https://www.sports-reference.com/cbb/schools/alabama-am/men/2026-gamelogs.html | E6: {=_xlfn.TEXTSPLIT( _xlfn.TEXTSPLIT(Team_Links[[#This Row],[GameLogs]],"https://www.sports-reference.com/cbb/schools/",,TRUE,0,), "/",,TRUE,0)} -> alabama-am
A7: 5 | B7: Alabama State | C7: https://www.sports-reference.com/cbb/schools/alabama-state/men/2026.html | D7: https://www.sports-reference.com/cbb/schools/alabama-state/men/2026-gamelogs.html | E7: {=_xlfn.TEXTSPLIT( _xlfn.TEXTSPLIT(Team_Links[[#This Row],[GameLogs]],"https://www.sports-reference.com/cbb/schools/",,TRUE,0,), "/",,TRUE,0)} -> alabama-state
A8: 6 | B8: Albany (NY) | C8: https://www.sports-reference.com/cbb/schools/albany-ny/men/2026.html | D8: https://www.sports-reference.com/cbb/schools/albany-ny/men/2026-gamelogs.html | E8: {=_xlfn.TEXTSPLIT( _xlfn.TEXTSPLIT(Team_Links[[#This Row],[GameLogs]],"https://www.sports-reference.com/cbb/schools/",,TRUE,0,), "/",,TRUE,0)} -> albany-ny
A9: 7 | B9: Alcorn State | C9: https://www.sports-reference.com/cbb/schools/alcorn-state/men/2026.html | D9: https://www.sports-reference.com/cbb/schools/alcorn-state/men/2026-gamelogs.html | E9: {=_xlfn.TEXTSPLIT( _xlfn.TEXTSPLIT(Team_Links[[#This Row],[GameLogs]],"https://www.sports-reference.com/cbb/schools/",,TRUE,0,), "/",,TRUE,0)} -> alcorn-state
A10: 8 | B10: American | C10: https://www.sports-reference.com/cbb/schools/american/men/2026.html | D10: https://www.sports-reference.com/cbb/schools/american/men/2026-gamelogs.html | E10: {=_xlfn.TEXTSPLIT( _xlfn.TEXTSPLIT(Team_Links[[#This Row],[GameLogs]],"https://www.sports-reference.com/cbb/schools/",,TRUE,0,), "/",,TRUE,0)} -> american
A11: 9 | B11: Appalachian State | C11: https://www.sports-reference.com/cbb/schools/appalachian-state/men/2026.html | D11: https://www.sports-reference.com/cbb/schools/appalachian-state/men/2026-gamelogs.html | E11: {=_xlfn.TEXTSPLIT( _xlfn.TEXTSPLIT(Team_Links[[#This Row],[GameLogs]],"https://www.sports-reference.com/cbb/schools/",,TRUE,0,), "/",,TRUE,0)} -> appalachian-state
A12: 10 | B12: Arizona | C12: https://www.sports-reference.com/cbb/schools/arizona/men/2026.html | D12: https://www.sports-reference.com/cbb/schools/arizona/men/2026-gamelogs.html | E12: {=_xlfn.TEXTSPLIT( _xlfn.TEXTSPLIT(Team_Links[[#This Row],[GameLogs]],"https://www.sports-reference.com/cbb/schools/",,TRUE,0,), "/",,TRUE,0)} -> arizona
A13: 11 | B13: Arizona State | C13: https://www.sports-reference.com/cbb/schools/arizona-state/men/2026.html | D13: https://www.sports-reference.com/cbb/schools/arizona-state/men/2026-gamelogs.html | E13: {=_xlfn.TEXTSPLIT( _xlfn.TEXTSPLIT(Team_Links[[#This Row],[GameLogs]],"https://www.sports-reference.com/cbb/schools/",,TRUE,0,), "/",,TRUE,0)} -> arizona-state
... A366: 364 | B366: Youngstown State | C366: https://www.sports-reference.com/cbb/schools/youngstown-state/men/2026.html | D366: https://www.sports-reference.com/cbb/schools/youngstown-state/men/2026-gamelogs.html | E366: {=_xlfn.TEXTSPLIT( _xlfn.TEXTSPLIT(Team_Links[[#This Row],[GameLogs]],"https://www.sports-reference.com/cbb/schools/",,TRUE,0,), "/",,TRUE,0)} -> youngstown-state

Sheet Teams
A1: Seed | B1: Region | C1: Team | D1: Hyperlink Name | E1: Logo
A2: 1 | B2: South | C2: Auburn | D2: =_xlfn.XLOOKUP(Teams[[#This Row],[Team]],Team_Links[School],Team_Links[PartialLink],,0,1) -> auburn | E2: =_xlfn.IMAGE(_xlfn.CONCAT("https://cdn.ssref.net/req/202510241/tlogo/ncaa/",TEXT(Teams[[#This Row],[Hyperlink Name]],),"-2025.png")) -> #VALUE!
A3: 16 | B3: South | C3: Alabama State | D3: =_xlfn.XLOOKUP(Teams[[#This Row],[Team]],Team_Links[School],Team_Links[PartialLink],,0,1) -> alabama-state | E3: =_xlfn.IMAGE(_xlfn.CONCAT("https://cdn.ssref.net/req/202510241/tlogo/ncaa/",TEXT(Teams[[#This Row],[Hyperlink Name]],),"-2025.png")) -> #VALUE!
A4: 8 | B4: South | C4: Louisville | D4: =_xlfn.XLOOKUP(Teams[[#This Row],[Team]],Team_Links[School],Team_Links[PartialLink],,0,1) -> louisville | E4: =_xlfn.IMAGE(_xlfn.CONCAT("https://cdn.ssref.net/req/202510241/tlogo/ncaa/",TEXT(Teams[[#This Row],[Hyperlink Name]],),"-2025.png")) -> #VALUE!
A5: 9 | B5: South | C5: Creighton | D5: =_xlfn.XLOOKUP(Teams[[#This Row],[Team]],Team_Links[School],Team_Links[PartialLink],,0,1) -> creighton | E5: =_xlfn.IMAGE(_xlfn.CONCAT("https://cdn.ssref.net/req/202510241/tlogo/ncaa/",TEXT(Teams[[#This Row],[Hyperlink Name]],),"-2025.png")) -> #VALUE!
A6: 5 | B6: South | C6: Michigan | D6: =_xlfn.XLOOKUP(Teams[[#This Row],[Team]],Team_Links[School],Team_Links[PartialLink],,0,1) -> michigan | E6: =_xlfn.IMAGE(_xlfn.CONCAT("https://cdn.ssref.net/req/202510241/tlogo/ncaa/",TEXT(Teams[[#This Row],[Hyperlink Name]],),"-2025.png")) -> #VALUE!
A7: 12 | B7: South | C7: UC San Diego | D7: =_xlfn.XLOOKUP(Teams[[#This Row],[Team]],Team_Links[School],Team_Links[PartialLink],,0,1) -> california-san-diego | E7: =_xlfn.IMAGE(_xlfn.CONCAT("https://cdn.ssref.net/req/202510241/tlogo/ncaa/",TEXT(Teams[[#This Row],[Hyperlink Name]],),"-2025.png")) -> #VALUE!
A8: 4 | B8: South | C8: Texas A&M | D8: =_xlfn.XLOOKUP(Teams[[#This Row],[Team]],Team_Links[School],Team_Links[PartialLink],,0,1) -> texas-am | E8: =_xlfn.IMAGE(_xlfn.CONCAT("https://cdn.ssref.net/req/202510241/tlogo/ncaa/",TEXT(Teams[[#This Row],[Hyperlink Name]],),"-2025.png")) -> #VALUE!
A9: 13 | B9: South | C9: Yale | D9: =_xlfn.XLOOKUP(Teams[[#This Row],[Team]],Team_Links[School],Team_Links[PartialLink],,0,1) -> yale | E9: =_xlfn.IMAGE(_xlfn.CONCAT("https://cdn.ssref.net/req/202510241/tlogo/ncaa/",TEXT(Teams[[#This Row],[Hyperlink Name]],),"-2025.png")) -> #VALUE!
A10: 6 | B10: South | C10: Mississippi | D10: =_xlfn.XLOOKUP(Teams[[#This Row],[Team]],Team_Links[School],Team_Links[PartialLink],,0,1) -> mississippi | E10: =_xlfn.IMAGE(_xlfn.CONCAT("https://cdn.ssref.net/req/202510241/tlogo/ncaa/",TEXT(Teams[[#This Row],[Hyperlink Name]],),"-2025.png")) -> #VALUE!
A11: 11 | B11: South | C11: North Carolina | D11: =_xlfn.XLOOKUP(Teams[[#This Row],[Team]],Team_Links[School],Team_Links[PartialLink],,0,1) -> north-carolina | E11: =_xlfn.IMAGE(_xlfn.CONCAT("https://cdn.ssref.net/req/202510241/tlogo/ncaa/",TEXT(Teams[[#This Row],[Hyperlink Name]],),"-2025.png")) -> #VALUE!
A12: 3 | B12: South | C12: Iowa State | D12: =_xlfn.XLOOKUP(Teams[[#This Row],[Team]],Team_Links[School],Team_Links[PartialLink],,0,1) -> iowa-state | E12: =_xlfn.IMAGE(_xlfn.CONCAT("https://cdn.ssref.net/req/202510241/tlogo/ncaa/",TEXT(Teams[[#This Row],[Hyperlink Name]],),"-2025.png")) -> #VALUE!
A13: 14 | B13: South | C13: Lipscomb | D13: =_xlfn.XLOOKUP(Teams[[#This Row],[Team]],Team_Links[School],Team_Links[PartialLink],,0,1) -> lipscomb | E13: =_xlfn.IMAGE(_xlfn.CONCAT("https://cdn.ssref.net/req/202510241/tlogo/ncaa/",TEXT(Teams[[#This Row],[Hyperlink Name]],),"-2025.png")) -> #VALUE!
... A65: 15 | B65: Midwest | C65: Wofford | D65: =_xlfn.XLOOKUP(Teams[[#This Row],[Team]],Team_Links[School],Team_Links[PartialLink],,0,1) -> wofford | E65: =_xlfn.IMAGE(_xlfn.CONCAT("https://cdn.ssref.net/req/202510241/tlogo/ncaa/",TEXT(Teams[[#This Row],[Hyperlink Name]],),"-2025.png")) -> #VALUE!

Sheet Games
G1: Tournament Picks for Multiple Players | S1: .
C3: Loser | D3: Seed Bonus | E3: Game # | F3: Seed | G3: Pairing | J3: Seed | K3: Score 1 | M3: Score 2 | O3: Winner | Q3: Evaluation
A5: =G5 -> Duke | B5: =I5 -> Mount St. Mary's | C5: =IF(O5="","",IF(A5=O5,B5,A5)) -> Mount St. Mary's | D5: =IF(SeedType=1,0,IF(SeedType=2,VLOOKUP(O5,SeedInfo,2,FALSE)*1,MAX(VLOOKUP(O5,SeedInfo,2,FALSE)-VLOOKUP(C5,SeedInfo,2,FALSE),0))) -> #REF! | E5: 1 | F5: {=_xlfn.XLOOKUP(G5,Teams[[#All],[Team]],Teams[[#All],[Seed]],0,0,1)} -> 1 | G5: Duke | H5: vs | I5: Mount St. Mary's | J5: {=_xlfn.XLOOKUP(I5,Teams[[#All],[Team]],Teams[[#All],[Seed]],0,0,1)} -> 16 | K5: =_xlfn.XLOOKUP(G5,Teams!$C:$C,Teams!$E:$E,,0,1) -> #VALUE! | L5: 0.98 | M5: =_xlfn.XLOOKUP(I5,Teams!$C:$C,Teams!$E:$E,,0,1) -> #VALUE! | N5: 0.02 | O5: =IF(L5>N5,G5,I5) -> Duke | P5: =_xlfn.XLOOKUP(O5,Teams!$C:$C,Teams!$E:$E,,0,1) -> #VALUE! | Q5: Duke: 491 - 10 :Mount St. Mary's | R5: =IF( O5=G5, IF(F5>J5,TRUE,FALSE), IF(J5>F5,TRUE,FALSE)) -> FALSE
A6: =G6 -> Mississippi State | B6: =I6 -> Baylor | C6: =IF(O6="","",IF(A6=O6,B6,A6)) -> Mississippi State | D6: =IF(SeedType=1,0,IF(SeedType=2,VLOOKUP(O6,SeedInfo,2,FALSE)*1,MAX(VLOOKUP(O6,SeedInfo,2,FALSE)-VLOOKUP(C6,SeedInfo,2,FALSE),0))) -> #REF! | E6: 2 | F6: {=_xlfn.XLOOKUP(G6,Teams[[#All],[Team]],Teams[[#All],[Seed]],0,0,1)} -> 8 | G6: Mississippi State | H6: vs | I6: Baylor | J6: {=_xlfn.XLOOKUP(I6,Teams[[#All],[Team]],Teams[[#All],[Seed]],0,0,1)} -> 9 | K6: =_xlfn.XLOOKUP(G6,Teams!$C:$C,Teams!$E:$E,,0,1) -> #VALUE! | L6: 0.34 | M6: =_xlfn.XLOOKUP(I6,Teams!$C:$C,Teams!$E:$E,,0,1) -> #VALUE! | N6: 0.66 | O6: =IF(L6>N6,G6,I6) -> Baylor | P6: =_xlfn.XLOOKUP(O6,Teams!$C:$C,Teams!$E:$E,,0,1) -> #VALUE! | Q6: Mississippi State: 168 - 333 :Baylor | R6: =IF( O6=G6, IF(F6>J6,TRUE,FALSE), IF(J6>F6,TRUE,FALSE)) -> TRUE
A7: =G7 -> Oregon | B7: =I7 -> Liberty | C7: =IF(O7="","",IF(A7=O7,B7,A7)) -> Oregon | D7: =IF(SeedType=1,0,IF(SeedType=2,VLOOKUP(O7,SeedInfo,2,FALSE)*1,MAX(VLOOKUP(O7,SeedInfo,2,FALSE)-VLOOKUP(C7,SeedInfo,2,FALSE),0))) -> #REF! | E7: 3 | F7: {=_xlfn.XLOOKUP(G7,Teams[[#All],[Team]],Teams[[#All],[Seed]],0,0,1)} -> 5 | G7: Oregon | H7: vs | I7: Liberty | J7: {=_xlfn.XLOOKUP(I7,Teams[[#All],[Team]],Teams[[#All],[Seed]],0,0,1)} -> 12 | K7: =_xlfn.XLOOKUP(G7,Teams!$C:$C,Teams!$E:$E,,0,1) -> #VALUE! | L7: 0.12 | M7: =_xlfn.XLOOKUP(I7,Teams!$C:$C,Teams!$E:$E,,0,1) -> #VALUE! | N7: 0.88 | O7: =IF(L7>N7,G7,I7) -> Liberty | P7: =_xlfn.XLOOKUP(O7,Teams!$C:$C,Teams!$E:$E,,0,1) -> #VALUE! | Q7: Oregon: 59 - 442 :Liberty | R7: =IF( O7=G7, IF(F7>J7,TRUE,FALSE), IF(J7>F7,TRUE,FALSE)) -> TRUE
A8: =G8 -> Arizona | B8: =I8 -> Akron | C8: =IF(O8="","",IF(A8=O8,B8,A8)) -> Arizona | D8: =IF(SeedType=1,0,IF(SeedType=2,VLOOKUP(O8,SeedInfo,2,FALSE)*1,MAX(VLOOKUP(O8,SeedInfo,2,FALSE)-VLOOKUP(C8,SeedInfo,2,FALSE),0))) -> #REF! | E8: 4 | F8: {=_xlfn.XLOOKUP(G8,Teams[[#All],[Team]],Teams[[#All],[Seed]],0,0,1)} -> 4 | G8: Arizona | H8: vs | I8: Akron | J8: {=_xlfn.XLOOKUP(I8,Teams[[#All],[Team]],Teams[[#All],[Seed]],0,0,1)} -> 13 | K8: =_xlfn.XLOOKUP(G8,Teams!$C:$C,Teams!$E:$E,,0,1) -> #VALUE! | L8: 0.12 | M8: =_xlfn.XLOOKUP(I8,Teams!$C:$C,Teams!$E:$E,,0,1) -> #VALUE! | N8: 0.88 | O8: =IF(L8>N8,G8,I8) -> Akron | P8: =_xlfn.XLOOKUP(O8,Teams!$C:$C,Teams!$E:$E,,0,1) -> #VALUE! | Q8: UPSET! Normal winner is Arizona | R8: =IF( O8=G8, IF(F8>J8,TRUE,FALSE), IF(J8>F8,TRUE,FALSE)) -> TRUE
A9: =G9 -> Brigham Young | B9: =I9 -> Virginia Commonwealth | C9: =IF(O9="","",IF(A9=O9,B9,A9)) -> Virginia Commonwealth | D9: =IF(SeedType=1,0,IF(SeedType=2,VLOOKUP(O9,SeedInfo,2,FALSE)*1,MAX(VLOOKUP(O9,SeedInfo,2,FALSE)-VLOOKUP(C9,SeedInfo,2,FALSE),0))) -> #REF! | E9: 5 | F9: {=_xlfn.XLOOKUP(G9,Teams[[#All],[Team]],Teams[[#All],[Seed]],0,0,1)} -> 6 | G9: Brigham Young | H9: vs | I9: Virginia Commonwealth | J9: {=_xlfn.XLOOKUP(I9,Teams[[#All],[Team]],Teams[[#All],[Seed]],0,0,1)} -> 11 | K9: =_xlfn.XLOOKUP(G9,Teams!$C:$C,Teams!$E:$E,,0,1) -> #VALUE! | L9: 0.72 | M9: =_xlfn.XLOOKUP(I9,Teams!$C:$C,Teams!$E:$E,,0,1) -> #VALUE! | N9: 0.28 | O9: =IF(L9>N9,G9,I9) -> Brigham Young | P9: =_xlfn.XLOOKUP(O9,Teams!$C:$C,Teams!$E:$E,,0,1) -> #VALUE! | Q9: Brigham Young: 360 - 141 :Virginia Commonwealth | R9: =IF( O9=G9, IF(F9>J9,TRUE,FALSE), IF(J9>F9,TRUE,FALSE)) -> FALSE
A10: =G10 -> Wisconsin | B10: =I10 -> Montana | C10: =IF(O10="","",IF(A10=O10,B10,A10)) -> Montana | D10: =IF(SeedType=1,0,IF(SeedType=2,VLOOKUP(O10,SeedInfo,2,FALSE)*1,MAX(VLOOKUP(O10,SeedInfo,2,FALSE)-VLOOKUP(C10,SeedInfo,2,FALSE),0))) -> #REF! | E10: 6 | F10: {=_xlfn.XLOOKUP(G10,Teams[[#All],[Team]],Teams[[#All],[Seed]],0,0,1)} -> 3 | G10: Wisconsin | H10: vs | I10: Montana | J10: {=_xlfn.XLOOKUP(I10,Teams[[#All],[Team]],Teams[[#All],[Seed]],0,0,1)} -> 14 | K10: =_xlfn.XLOOKUP(G10,Teams!$C:$C,Teams!$E:$E,,0,1) -> #VALUE! | L10: 0.94 | M10: =_xlfn.XLOOKUP(I10,Teams!$C:$C,Teams!$E:$E,,0,1) -> #VALUE! | N10: 0.06 | O10: =IF(L10>N10,G10,I10) -> Wisconsin | P10: =_xlfn.XLOOKUP(O10,Teams!$C:$C,Teams!$E:$E,,0,1) -> #VALUE! | Q10: Wisconsin: 471 - 30 :Montana | R10: =IF( O10=G10, IF(F10>J10,TRUE,FALSE), IF(J10>F10,TRUE,FALSE)) -> FALSE
A11: =G11 -> Saint Mary's (CA) | B11: =I11 -> Vanderbilt | C11: =IF(O11="","",IF(A11=O11,B11,A11)) -> Vanderbilt | D11: =IF(SeedType=1,0,IF(SeedType=2,VLOOKUP(O11,SeedInfo,2,FALSE)*1,MAX(VLOOKUP(O11,SeedInfo,2,FALSE)-VLOOKUP(C11,SeedInfo,2,FALSE),0))) -> #REF! | E11: 7 | F11: {=_xlfn.XLOOKUP(G11,Teams[[#All],[Team]],Teams[[#All],[Seed]],0,0,1)} -> 7 | G11: Saint Mary's (CA) | H11: vs | I11: Vanderbilt | J11: {=_xlfn.XLOOKUP(I11,Teams[[#All],[Team]],Teams[[#All],[Seed]],0,0,1)} -> 10 | K11: =_xlfn.XLOOKUP(G11,Teams!$C:$C,Teams!$E:$E,,0,1) -> #VALUE! | L11: 0.71 | M11: =_xlfn.XLOOKUP(I11,Teams!$C:$C,Teams!$E:$E,,0,1) -> #VALUE! | N11: 0.29 | O11: =IF(L11>N11,G11,I11) -> Saint Mary's (CA) | P11: =_xlfn.XLOOKUP(O11,Teams!$C:$C,Teams!$E:$E,,0,1) -> #VALUE! | Q11: Saint Mary's (CA): 355 - 146 :Vanderbilt | R11: =IF( O11=G11, IF(F11>J11,TRUE,FALSE), IF(J11>F11,TRUE,FALSE)) -> FALSE
A12: =G12 -> Alabama | B12: =I12 -> Robert Morris | C12: =IF(O12="","",IF(A12=O12,B12,A12)) -> Robert Morris | D12: =IF(SeedType=1,0,IF(SeedType=2,VLOOKUP(O12,SeedInfo,2,FALSE)*1,MAX(VLOOKUP(O12,SeedInfo,2,FALSE)-VLOOKUP(C12,SeedInfo,2,FALSE),0))) -> #REF! | E12: 8 | F12: {=_xlfn.XLOOKUP(G12,Teams[[#All],[Team]],Teams[[#All],[Seed]],0,0,1)} -> 2 | G12: Alabama | H12: vs | I12: Robert Morris | J12: {=_xlfn.XLOOKUP(I12,Teams[[#All],[Team]],Teams[[#All],[Seed]],0,0,1)} -> 15 | K12: =_xlfn.XLOOKUP(G12,Teams!$C:$C,Teams!$E:$E,,0,1) -> #VALUE! | L12: 0.94 | M12: =_xlfn.XLOOKUP(I12,Teams!$C:$C,Teams!$E:$E,,0,1) -> #VALUE! | N12: 0.06 | O12: =IF(L12>N12,G12,I12) -> Alabama | P12: =_xlfn.XLOOKUP(O12,Teams!$C:$C,Teams!$E:$E,,0,1) -> #VALUE! | Q12: Alabama: 472 - 29 :Robert Morris | R12: =IF( O12=G12, IF(F12>J12,TRUE,FALSE), IF(J12>F12,TRUE,FALSE)) -> FALSE
A13: =G13 -> Florida | B13: =I13 -> Norfolk State | C13: =IF(O13="","",IF(A13=O13,B13,A13)) -> Norfolk State | D13: =IF(SeedType=1,0,IF(SeedType=2,VLOOKUP(O13,SeedInfo,2,FALSE)*1,MAX(VLOOKUP(O13,SeedInfo,2,FALSE)-VLOOKUP(C13,SeedInfo,2,FALSE),0))) -> #REF! | E13: 9 | F13: {=_xlfn.XLOOKUP(G13,Teams[[#All],[Team]],Teams[[#All],[Seed]],0,0,1)} -> 1 | G13: Florida | H13: vs | I13: Norfolk State | J13: {=_xlfn.XLOOKUP(I13,Teams[[#All],[Team]],Teams[[#All],[Seed]],0,0,1)} -> 16 | K13: =_xlfn.XLOOKUP(G13,Teams!$C:$C,Teams!$E:$E,,0,1) -> #VALUE! | L13: 1 | M13: =_xlfn.XLOOKUP(I13,Teams!$C:$C,Teams!$E:$E,,0,1) -> #VALUE! | N13: 0 | O13: =IF(L13>N13,G13,I13) -> Florida | P13: =_xlfn.XLOOKUP(O13,Teams!$C:$C,Teams!$E:$E,,0,1) -> #VALUE! | Q13: Florida: 501 - 0 :Norfolk State | R13: =IF( O13=G13, IF(F13>J13,TRUE,FALSE), IF(J13>F13,TRUE,FALSE)) -> FALSE
A14: =G14 -> Connecticut | B14: =I14 -> Oklahoma | C14: =IF(O14="","",IF(A14=O14,B14,A14)) -> Oklahoma | D14: =IF(SeedType=1,0,IF(SeedType=2,VLOOKUP(O14,SeedInfo,2,FALSE)*1,MAX(VLOOKUP(O14,SeedInfo,2,FALSE)-VLOOKUP(C14,SeedInfo,2,FALSE),0))) -> #REF! | E14: 10 | F14: {=_xlfn.XLOOKUP(G14,Teams[[#All],[Team]],Teams[[#All],[Seed]],0,0,1)} -> 8 | G14: Connecticut | H14: vs | I14: Oklahoma | J14: {=_xlfn.XLOOKUP(I14,Teams[[#All],[Team]],Teams[[#All],[Seed]],0,0,1)} -> 9 | K14: =_xlfn.XLOOKUP(G14,Teams!$C:$C,Teams!$E:$E,,0,1) -> #VALUE! | L14: 0.83 | M14: =_xlfn.XLOOKUP(I14,Teams!$C:$C,Teams!$E:$E,,0,1) -> #VALUE! | N14: 0.17 | O14: =IF(L14>N14,G14,I14) -> Connecticut | P14: =_xlfn.XLOOKUP(O14,Teams!$C:$C,Teams!$E:$E,,0,1) -> #VALUE! | Q14: Connecticut: 418 - 83 :Oklahoma | R14: =IF( O14=G14, IF(F14>J14,TRUE,FALSE), IF(J14>F14,TRUE,FALSE)) -> FALSE
A15: =G15 -> Memphis | B15: =I15 -> Colorado State | C15: =IF(O15="","",IF(A15=O15,B15,A15)) -> Memphis | D15: =IF(SeedType=1,0,IF(SeedType=2,VLOOKUP(O15,SeedInfo,2,FALSE)*1,MAX(VLOOKUP(O15,SeedInfo,2,FALSE)-VLOOKUP(C15,SeedInfo,2,FALSE),0))) -> #REF! | E15: 11 | F15: {=_xlfn.XLOOKUP(G15,Teams[[#All],[Team]],Teams[[#All],[Seed]],0,0,1)} -> 5 | G15: Memphis | H15: vs | I15: Colorado State | J15: {=_xlfn.XLOOKUP(I15,Teams[[#All],[Team]],Teams[[#All],[Seed]],0,0,1)} -> 12 | K15: =_xlfn.XLOOKUP(G15,Teams!$C:$C,Teams!$E:$E,,0,1) -> #VALUE! | L15: 0.31 | M15: =_xlfn.XLOOKUP(I15,Teams!$C:$C,Teams!$E:$E,,0,1) -> #VALUE! | N15: 0.69 | O15: =IF(L15>N15,G15,I15) -> Colorado State | P15: =_xlfn.XLOOKUP(O15,Teams!$C:$C,Teams!$E:$E,,0,1) -> #VALUE! | Q15: Memphis: 153 - 348 :Colorado State | R15: =IF( O15=G15, IF(F15>J15,TRUE,FALSE), IF(J15>F15,TRUE,FALSE)) -> TRUE
A16: =G16 -> Maryland | B16: =I16 -> Grand Canyon | C16: =IF(O16="","",IF(A16=O16,B16,A16)) -> Maryland | D16: =IF(SeedType=1,0,IF(SeedType=2,VLOOKUP(O16,SeedInfo,2,FALSE)*1,MAX(VLOOKUP(O16,SeedInfo,2,FALSE)-VLOOKUP(C16,SeedInfo,2,FALSE),0))) -> #REF! | E16: 12 | F16: {=_xlfn.XLOOKUP(G16,Teams[[#All],[Team]],Teams[[#All],[Seed]],0,0,1)} -> 4 | G16: Maryland | H16: vs | I16: Grand Canyon | J16: {=_xlfn.XLOOKUP(I16,Teams[[#All],[Team]],Teams[[#All],[Seed]],0,0,1)} -> 13 | K16: =_xlfn.XLOOKUP(G16,Teams!$C:$C,Teams!$E:$E,,0,1) -> #VALUE! | L16: 0.22 | M16: =_xlfn.XLOOKUP(I16,Teams!$C:$C,Teams!$E:$E,,0,1) -> #VALUE! | N16: 0.78 | O16: =IF(L16>N16,G16,I16) -> Grand Canyon | P16: =_xlfn.XLOOKUP(O16,Teams!$C:$C,Teams!$E:$E,,0,1) -> #VALUE! | Q16: Maryland: 110 - 391 :Grand Canyon | R16: =IF( O16=G16, IF(F16>J16,TRUE,FALSE), IF(J16>F16,TRUE,FALSE)) -> TRUE
... A36: =G36 -> Tennessee | B36: =I36 -> Wofford | C36: =IF(O36="","",IF(A36=O36,B36,A36)) -> Wofford | D36: =IF(SeedType=1,0,IF(SeedType=2,VLOOKUP(O36,SeedInfo,2,FALSE)*1,MAX(VLOOKUP(O36,SeedInfo,2,FALSE)-VLOOKUP(C36,SeedInfo,2,FALSE),0))) -> #REF! | E36: 32 | F36: {=_xlfn.XLOOKUP(G36,Teams[[#All],[Team]],Teams[[#All],[Seed]],0,0,1)} -> 2 | G36: Tennessee | H36: vs | I36: Wofford | J36: {=_xlfn.XLOOKUP(I36,Teams[[#All],[Team]],Teams[[#All],[Seed]],0,0,1)} -> 15 | K36: =_xlfn.XLOOKUP(G36,Teams!$C:$C,Teams!$E:$E,,0,1) -> #VALUE! | L36: 0.72 | M36: =_xlfn.XLOOKUP(I36,Teams!$C:$C,Teams!$E:$E,,0,1) -> #VALUE! | N36: 0.28 | O36: =IF(L36>N36,G36,I36) -> Tennessee | P36: =_xlfn.XLOOKUP(O36,Teams!$C:$C,Teams!$E:$E,,0,1) -> #VALUE! | Q36: Tennessee: 363 - 138 :Wofford | R36: =IF( O36=G36, IF(F36>J36,TRUE,FALSE), IF(J36>F36,TRUE,FALSE)) -> FALSE
E37: Game # | F37: =Bracket!F2 -> Second Round | O37: Winner
A38: =G38 -> Duke | B38: =I38 -> Baylor | C38: =IF(O38="","",IF(A38=O38,B38,A38)) -> Baylor | D38: =IF(SeedType=1,0,IF(SeedType=2,VLOOKUP(O38,SeedInfo,2,FALSE)*2,MAX(VLOOKUP(O38,SeedInfo,2,FALSE)-VLOOKUP(C38,SeedInfo,2,FALSE),0))) -> #REF! | E38: =Bracket!F7 -> 33 | F38: {=_xlfn.XLOOKUP(G38,Teams[[#All],[Team]],Teams[[#All],[Seed]],0,0,1)} -> 1 | G38: Duke | H38: vs | I38: Baylor | J38: {=_xlfn.XLOOKUP(I38,Teams[[#All],[Team]],Teams[[#All],[Seed]],0,0,1)} -> 9 | K38: =_xlfn.XLOOKUP(G38,Teams!$C:$C,Teams!$E:$E,,0,1) -> #VALUE! | L38: 0.85 | M38: =_xlfn.XLOOKUP(I38,Teams!$C:$C,Teams!$E:$E,,0,1) -> #VALUE! | N38: 0.15 | O38: =IF(L38>N38,G38,I38) -> Duke | P38: =_xlfn.XLOOKUP(O38,Teams!$C:$C,Teams!$E:$E,,0,1) -> #VALUE! | Q38: Duke: 426 - 75 :Baylor | R38: =IF( O38=G38, IF(F38>J38,TRUE,FALSE), IF(J38>F38,TRUE,FALSE)) -> FALSE
A39: =G39 -> Liberty | B39: =I39 -> Akron | C39: =IF(O39="","",IF(A39=O39,B39,A39)) -> Liberty | D39: =IF(SeedType=1,0,IF(SeedType=2,VLOOKUP(O39,SeedInfo,2,FALSE)*2,MAX(VLOOKUP(O39,SeedInfo,2,FALSE)-VLOOKUP(C39,SeedInfo,2,FALSE),0))) -> #REF! | E39: 34 | F39: {=_xlfn.XLOOKUP(G39,Teams[[#All],[Team]],Teams[[#All],[Seed]],0,0,1)} -> 12 | G39: Liberty | H39: vs | I39: Akron | J39: {=_xlfn.XLOOKUP(I39,Teams[[#All],[Team]],Teams[[#All],[Seed]],0,0,1)} -> 13 | K39: =_xlfn.XLOOKUP(G39,Teams!$C:$C,Teams!$E:$E,,0,1) -> #VALUE! | L39: 0.46 | M39: =_xlfn.XLOOKUP(I39,Teams!$C:$C,Teams!$E:$E,,0,1) -> #VALUE! | N39: 0.54 | O39: =IF(L39>N39,G39,I39) -> Akron | P39: =_xlfn.XLOOKUP(O39,Teams!$C:$C,Teams!$E:$E,,0,1) -> #VALUE! | Q39: Liberty: 229 - 272 :Akron | R39: =IF( O39=G39, IF(F39>J39,TRUE,FALSE), IF(J39>F39,TRUE,FALSE)) -> TRUE
A40: =G40 -> Brigham Young | B40: =I40 -> Wisconsin | C40: =IF(O40="","",IF(A40=O40,B40,A40)) -> Wisconsin | D40: =IF(SeedType=1,0,IF(SeedType=2,VLOOKUP(O40,SeedInfo,2,FALSE)*2,MAX(VLOOKUP(O40,SeedInfo,2,FALSE)-VLOOKUP(C40,SeedInfo,2,FALSE),0))) -> #REF! | E40: 35 | F40: {=_xlfn.XLOOKUP(G40,Teams[[#All],[Team]],Teams[[#All],[Seed]],0,0,1)} -> 6 | G40: Brigham Young | H40: vs | I40: Wisconsin | J40: {=_xlfn.XLOOKUP(I40,Teams[[#All],[Team]],Teams[[#All],[Seed]],0,0,1)} -> 3 | K40: =_xlfn.XLOOKUP(G40,Teams!$C:$C,Teams!$E:$E,,0,1) -> #VALUE! | L40: 0.58 | M40: =_xlfn.XLOOKUP(I40,Teams!$C:$C,Teams!$E:$E,,0,1) -> #VALUE! | N40: 0.42 | O40: =IF(L40>N40,G40,I40) -> Brigham Young | P40: =_xlfn.XLOOKUP(O40,Teams!$C:$C,Teams!$E:$E,,0,1) -> #VALUE! | Q40: Brigham Young: 291 - 210 :Wisconsin | R40: =IF( O40=G40, IF(F40>J40,TRUE,FALSE), IF(J40>F40,TRUE,FALSE)) -> TRUE
A41: =G41 -> Saint Mary's (CA) | B41: =I41 -> Alabama | C41: =IF(O41="","",IF(A41=O41,B41,A41)) -> Alabama | D41: =IF(SeedType=1,0,IF(SeedType=2,VLOOKUP(O41,SeedInfo,2,FALSE)*2,MAX(VLOOKUP(O41,SeedInfo,2,FALSE)-VLOOKUP(C41,SeedInfo,2,FALSE),0))) -> #REF! | E41: 36 | F41: {=_xlfn.XLOOKUP(G41,Teams[[#All],[Team]],Teams[[#All],[Seed]],0,0,1)} -> 7 | G41: Saint Mary's (CA) | H41: vs | I41: Alabama | J41: {=_xlfn.XLOOKUP(I41,Teams[[#All],[Team]],Teams[[#All],[Seed]],0,0,1)} -> 2 | K41: =_xlfn.XLOOKUP(G41,Teams!$C:$C,Teams!$E:$E,,0,1) -> #VALUE! | L41: 0.51 | M41: =_xlfn.XLOOKUP(I41,Teams!$C:$C,Teams!$E:$E,,0,1) -> #VALUE! | N41: 0.49 | O41: =IF(L41>N41,G41,I41) -> Saint Mary's (CA) | P41: =_xlfn.XLOOKUP(O41,Teams!$C:$C,Teams!$E:$E,,0,1) -> #VALUE! | Q41: Saint Mary's (CA): 256 - 245 :Alabama | R41: =IF( O41=G41, IF(F41>J41,TRUE,FALSE), IF(J41>F41,TRUE,FALSE)) -> TRUE
A42: =G42 -> Florida | B42: =I42 -> Connecticut | C42: =IF(O42="","",IF(A42=O42,B42,A42)) -> Connecticut | D42: =IF(SeedType=1,0,IF(SeedType=2,VLOOKUP(O42,SeedInfo,2,FALSE)*2,MAX(VLOOKUP(O42,SeedInfo,2,FALSE)-VLOOKUP(C42,SeedInfo,2,FALSE),0))) -> #REF! | E42: 37 | F42: {=_xlfn.XLOOKUP(G42,Teams[[#All],[Team]],Teams[[#All],[Seed]],0,0,1)} -> 1 | G42: Florida | H42: vs | I42: Connecticut | J42: {=_xlfn.XLOOKUP(I42,Teams[[#All],[Team]],Teams[[#All],[Seed]],0,0,1)} -> 8 | K42: =_xlfn.XLOOKUP(G42,Teams!$C:$C,Teams!$E:$E,,0,1) -> #VALUE! | L42: 0.8 | M42: =_xlfn.XLOOKUP(I42,Teams!$C:$C,Teams!$E:$E,,0,1) -> #VALUE! | N42: 0.2 | O42: =IF(L42>N42,G42,I42) -> Florida | P42: =_xlfn.XLOOKUP(O42,Teams!$C:$C,Teams!$E:$E,,0,1) -> #VALUE! | Q42: Florida: 399 - 102 :Connecticut | R42: =IF( O42=G42, IF(F42>J42,TRUE,FALSE), IF(J42>F42,TRUE,FALSE)) -> FALSE
A43: =G43 -> Colorado State | B43: =I43 -> Grand Canyon | C43: =IF(O43="","",IF(A43=O43,B43,A43)) -> Colorado State | D43: =IF(SeedType=1,0,IF(SeedType=2,VLOOKUP(O43,SeedInfo,2,FALSE)*2,MAX(VLOOKUP(O43,SeedInfo,2,FALSE)-VLOOKUP(C43,SeedInfo,2,FALSE),0))) -> #REF! | E43: 38 | F43: {=_xlfn.XLOOKUP(G43,Teams[[#All],[Team]],Teams[[#All],[Seed]],0,0,1)} -> 12 | G43: Colorado State | H43: vs | I43: Grand Canyon | J43: {=_xlfn.XLOOKUP(I43,Teams[[#All],[Team]],Teams[[#All],[Seed]],0,0,1)} -> 13 | K43: =_xlfn.XLOOKUP(G43,Teams!$C:$C,Teams!$E:$E,,0,1) -> #VALUE! | L43: 0.23 | M43: =_xlfn.XLOOKUP(I43,Teams!$C:$C,Teams!$E:$E,,0,1) -> #VALUE! | N43: 0.77 | O43: =IF(L43>N43,G43,I43) -> Grand Canyon | P43: =_xlfn.XLOOKUP(O43,Teams!$C:$C,Teams!$E:$E,,0,1) -> #VALUE! | Q43: Colorado State: 114 - 387 :Grand Canyon | R43: =IF( O43=G43, IF(F43>J43,TRUE,FALSE), IF(J43>F43,TRUE,FALSE)) -> TRUE
A44: =G44 -> Missouri | B44: =I44 -> Texas Tech | C44: =IF(O44="","",IF(A44=O44,B44,A44)) -> Missouri | D44: =IF(SeedType=1,0,IF(SeedType=2,VLOOKUP(O44,SeedInfo,2,FALSE)*2,MAX(VLOOKUP(O44,SeedInfo,2,FALSE)-VLOOKUP(C44,SeedInfo,2,FALSE),0))) -> #REF! | E44: 39 | F44: {=_xlfn.XLOOKUP(G44,Teams[[#All],[Team]],Teams[[#All],[Seed]],0,0,1)} -> 6 | G44: Missouri | H44: vs | I44: Texas Tech | J44: {=_xlfn.XLOOKUP(I44,Teams[[#All],[Team]],Teams[[#All],[Seed]],0,0,1)} -> 3 | K44: =_xlfn.XLOOKUP(G44,Teams!$C:$C,Teams!$E:$E,,0,1) -> #VALUE! | L44: 0.11 | M44: =_xlfn.XLOOKUP(I44,Teams!$C:$C,Teams!$E:$E,,0,1) -> #VALUE! | N44: 0.89 | O44: =IF(L44>N44,G44,I44) -> Texas Tech | P44: =_xlfn.XLOOKUP(O44,Teams!$C:$C,Teams!$E:$E,,0,1) -> #VALUE! | Q44: Missouri: 57 - 444 :Texas Tech | R44: =IF( O44=G44, IF(F44>J44,TRUE,FALSE), IF(J44>F44,TRUE,FALSE)) -> FALSE
A45: =G45 -> Arkansas | B45: =I45 -> St. John's (NY) | C45: =IF(O45="","",IF(A45=O45,B45,A45)) -> Arkansas | D45: =IF(SeedType=1,0,IF(SeedType=2,VLOOKUP(O45,SeedInfo,2,FALSE)*2,MAX(VLOOKUP(O45,SeedInfo,2,FALSE)-VLOOKUP(C45,SeedInfo,2,FALSE),0))) -> #REF! | E45: 40 | F45: {=_xlfn.XLOOKUP(G45,Teams[[#All],[Team]],Teams[[#All],[Seed]],0,0,1)} -> 10 | G45: Arkansas | H45: vs | I45: St. John's (NY) | J45: {=_xlfn.XLOOKUP(I45,Teams[[#All],[Team]],Teams[[#All],[Seed]],0,0,1)} -> 2 | K45: =_xlfn.XLOOKUP(G45,Teams!$C:$C,Teams!$E:$E,,0,1) -> #VALUE! | L45: 0.47 | M45: =_xlfn.XLOOKUP(I45,Teams!$C:$C,Teams!$E:$E,,0,1) -> #VALUE! | N45: 0.53 | O45: =IF(L45>N45,G45,I45) -> St. John's (NY) | P45: =_xlfn.XLOOKUP(O45,Teams!$C:$C,Teams!$E:$E,,0,1) -> #VALUE! | Q45: Arkansas: 234 - 267 :St. John's (NY) | R45: =IF( O45=G45, IF(F45>J45,TRUE,FALSE), IF(J45>F45,TRUE,FALSE)) -> FALSE
A46: =G46 -> Auburn | B46: =I46 -> Louisville | C46: =IF(O46="","",IF(A46=O46,B46,A46)) -> Auburn | D46: =IF(SeedType=1,0,IF(SeedType=2,VLOOKUP(O46,SeedInfo,2,FALSE)*2,MAX(VLOOKUP(O46,SeedInfo,2,FALSE)-VLOOKUP(C46,SeedInfo,2,FALSE),0))) -> #REF! | E46: 41 | F46: {=_xlfn.XLOOKUP(G46,Teams[[#All],[Team]],Teams[[#All],[Seed]],0,0,1)} -> 1 | G46: Auburn | H46: vs | I46: Louisville | J46: {=_xlfn.XLOOKUP(I46,Teams[[#All],[Team]],Teams[[#All],[Seed]],0,0,1)} -> 8 | K46: =_xlfn.XLOOKUP(G46,Teams!$C:$C,Teams!$E:$E,,0,1) -> #VALUE! | L46: 0.5 | M46: =_xlfn.XLOOKUP(I46,Teams!$C:$C,Teams!$E:$E,,0,1) -> #VALUE! | N46: 0.5 | O46: =IF(L46>N46,G46,I46) -> Louisville | P46: =_xlfn.XLOOKUP(O46,Teams!$C:$C,Teams!$E:$E,,0,1) -> #VALUE! | Q46: Auburn: 253 - 248 :Louisville | R46: =IF( O46=G46, IF(F46>J46,TRUE,FALSE), IF(J46>F46,TRUE,FALSE)) -> TRUE
A47: =G47 -> Michigan | B47: =I47 -> Yale | C47: =IF(O47="","",IF(A47=O47,B47,A47)) -> Yale | D47: =IF(SeedType=1,0,IF(SeedType=2,VLOOKUP(O47,SeedInfo,2,FALSE)*2,MAX(VLOOKUP(O47,SeedInfo,2,FALSE)-VLOOKUP(C47,SeedInfo,2,FALSE),0))) -> #REF! | E47: 42 | F47: {=_xlfn.XLOOKUP(G47,Teams[[#All],[Team]],Teams[[#All],[Seed]],0,0,1)} -> 5 | G47: Michigan | H47: vs | I47: Yale | J47: {=_xlfn.XLOOKUP(I47,Teams[[#All],[Team]],Teams[[#All],[Seed]],0,0,1)} -> 13 | K47: =_xlfn.XLOOKUP(G47,Teams!$C:$C,Teams!$E:$E,,0,1) -> #VALUE! | L47: 0.77 | M47: =_xlfn.XLOOKUP(I47,Teams!$C:$C,Teams!$E:$E,,0,1) -> #VALUE! | N47: 0.23 | O47: =IF(L47>N47,G47,I47) -> Michigan | P47: =_xlfn.XLOOKUP(O47,Teams!$C:$C,Teams!$E:$E,,0,1) -> #VALUE! | Q47: Michigan: 384 - 117 :Yale | R47: =IF( O47=G47, IF(F47>J47,TRUE,FALSE), IF(J47>F47,TRUE,FALSE)) -> FALSE
A48: =G48 -> North Carolina | B48: =I48 -> Iowa State | C48: =IF(O48="","",IF(A48=O48,B48,A48)) -> Iowa State | D48: =IF(SeedType=1,0,IF(SeedType=2,VLOOKUP(O48,SeedInfo,2,FALSE)*2,MAX(VLOOKUP(O48,SeedInfo,2,FALSE)-VLOOKUP(C48,SeedInfo,2,FALSE),0))) -> #REF! | E48: 43 | F48: {=_xlfn.XLOOKUP(G48,Teams[[#All],[Team]],Teams[[#All],[Seed]],0,0,1)} -> 11 | G48: North Carolina | H48: vs | I48: Iowa State | J48: {=_xlfn.XLOOKUP(I48,Teams[[#All],[Team]],Teams[[#All],[Seed]],0,0,1)} -> 3 | K48: =_xlfn.XLOOKUP(G48,Teams!$C:$C,Teams!$E:$E,,0,1) -> #VALUE! | L48: 0.55 | M48: =_xlfn.XLOOKUP(I48,Teams!$C:$C,Teams!$E:$E,,0,1) -> #VALUE! | N48: 0.45 | O48: =IF(L48>N48,G48,I48) -> North Carolina | P48: =_xlfn.XLOOKUP(O48,Teams!$C:$C,Teams!$E:$E,,0,1) -> #VALUE! | Q48: UPSET! Normal winner is Iowa State | R48: =IF( O48=G48, IF(F48>J48,TRUE,FALSE), IF(J48>F48,TRUE,FALSE)) -> TRUE
A49: =G49 -> New Mexico | B49: =I49 -> Michigan State | C49: =IF(O49="","",IF(A49=O49,B49,A49)) -> Michigan State | D49: =IF(SeedType=1,0,IF(SeedType=2,VLOOKUP(O49,SeedInfo,2,FALSE)*2,MAX(VLOOKUP(O49,SeedInfo,2,FALSE)-VLOOKUP(C49,SeedInfo,2,FALSE),0))) -> #REF! | E49: 44 | F49: {=_xlfn.XLOOKUP(G49,Teams[[#All],[Team]],Teams[[#All],[Seed]],0,0,1)} -> 10 | G49: New Mexico | H49: vs | I49: Michigan State | J49: {=_xlfn.XLOOKUP(I49,Teams[[#All],[Team]],Teams[[#All],[Seed]],0,0,1)} -> 2 | K49: =_xlfn.XLOOKUP(G49,Teams!$C:$C,Teams!$E:$E,,0,1) -> #VALUE! | L49: 0.56 | M49: =_xlfn.XLOOKUP(I49,Teams!$C:$C,Teams!$E:$E,,0,1) -> #VALUE! | N49: 0.44 | O49: =IF(L49>N49,G49,I49) -> New Mexico | P49: =_xlfn.XLOOKUP(O49,Teams!$C:$C,Teams!$E:$E,,0,1) -> #VALUE! | Q49: UPSET! Normal winner is Michigan State | R49: =IF( O49=G49, IF(F49>J49,TRUE,FALSE), IF(J49>F49,TRUE,FALSE)) -> TRUE
A50: =G50 -> Houston | B50: =I50 -> Gonzaga | C50: =IF(O50="","",IF(A50=O50,B50,A50)) -> Houston | D50: =IF(SeedType=1,0,IF(SeedType=2,VLOOKUP(O50,SeedInfo,2,FALSE)*2,MAX(VLOOKUP(O50,SeedInfo,2,FALSE)-VLOOKUP(C50,SeedInfo,2,FALSE),0))) -> #REF! | E50: 45 | F50: {=_xlfn.XLOOKUP(G50,Teams[[#All],[Team]],Teams[[#All],[Seed]],0,0,1)} -> 1 | G50: Houston | H50: vs | I50: Gonzaga | J50: {=_xlfn.XLOOKUP(I50,Teams[[#All],[Team]],Teams[[#All],[Seed]],0,0,1)} -> 8 | K50: =_xlfn.XLOOKUP(G50,Teams!$C:$C,Teams!$E:$E,,0,1) -> #VALUE! | L50: 0.44 | M50: =_xlfn.XLOOKUP(I50,Teams!$C:$C,Teams!$E:$E,,0,1) -> #VALUE! | N50: 0.56 | O50: =IF(L50>N50,G50,I50) -> Gonzaga | P50: =_xlfn.XLOOKUP(O50,Teams!$C:$C,Teams!$E:$E,,0,1) -> #VALUE! | Q50: Houston: 222 - 279 :Gonzaga | R50: =IF( O50=G50, IF(F50>J50,TRUE,FALSE), IF(J50>F50,TRUE,FALSE)) -> TRUE
... A53: =G53 -> UCLA | B53: =I53 -> Tennessee | C53: =IF(O53="","",IF(A53=O53,B53,A53)) -> UCLA | D53: =IF(SeedType=1,0,IF(SeedType=2,VLOOKUP(O53,SeedInfo,2,FALSE)*2,MAX(VLOOKUP(O53,SeedInfo,2,FALSE)-VLOOKUP(C53,SeedInfo,2,FALSE),0))) -> #REF! | E53: 48 | F53: {=_xlfn.XLOOKUP(G53,Teams[[#All],[Team]],Teams[[#All],[Seed]],0,0,1)} -> 7 | G53: UCLA | H53: vs | I53: Tennessee | J53: {=_xlfn.XLOOKUP(I53,Teams[[#All],[Team]],Teams[[#All],[Seed]],0,0,1)} -> 2 | K53: =_xlfn.XLOOKUP(G53,Teams!$C:$C,Teams!$E:$E,,0,1) -> #VALUE! | L53: 0.43 | M53: =_xlfn.XLOOKUP(I53,Teams!$C:$C,Teams!$E:$E,,0,1) -> #VALUE! | N53: 0.57 | O53: =IF(L53>N53,G53,I53) -> Tennessee | P53: =_xlfn.XLOOKUP(O53,Teams!$C:$C,Teams!$E:$E,,0,1) -> #VALUE! | Q53: UCLA: 214 - 287 :Tennessee | R53: =IF( O53=G53, IF(F53>J53,TRUE,FALSE), IF(J53>F53,TRUE,FALSE)) -> FALSE
E54: Game # | F54: =Bracket!I2 -> Sweet 16 | O54: Winner
A55: =G55 -> Duke | B55: =I55 -> Akron | C55: =IF(O55="","",IF(A55=O55,B55,A55)) -> Akron | D55: =IF(SeedType=1,0,IF(SeedType=2,VLOOKUP(O55,SeedInfo,2,FALSE)*3,MAX(VLOOKUP(O55,SeedInfo,2,FALSE)-VLOOKUP(C55,SeedInfo,2,FALSE),0))) -> #REF! | E55: 49 | F55: {=_xlfn.XLOOKUP(G55,Teams[[#All],[Team]],Teams[[#All],[Seed]],0,0,1)} -> 1 | G55: Duke | H55: vs | I55: Akron | J55: {=_xlfn.XLOOKUP(I55,Teams[[#All],[Team]],Teams[[#All],[Seed]],0,0,1)} -> 13 | K55: =_xlfn.XLOOKUP(G55,Teams!$C:$C,Teams!$E:$E,,0,1) -> #VALUE! | L55: 0.78 | M55: =_xlfn.XLOOKUP(I55,Teams!$C:$C,Teams!$E:$E,,0,1) -> #VALUE! | N55: 0.22 | O55: =IF(L55>N55,G55,I55) -> Duke | P55: =_xlfn.XLOOKUP(O55,Teams!$C:$C,Teams!$E:$E,,0,1) -> #VALUE! | Q55: Duke: 391 - 110 :Akron | R55: =IF( O55=G55, IF(F55>J55,TRUE,FALSE), IF(J55>F55,TRUE,FALSE)) -> FALSE
A56: =G56 -> Brigham Young | B56: =I56 -> Saint Mary's (CA) | C56: =IF(O56="","",IF(A56=O56,B56,A56)) -> Brigham Young | D56: =IF(SeedType=1,0,IF(SeedType=2,VLOOKUP(O56,SeedInfo,2,FALSE)*3,MAX(VLOOKUP(O56,SeedInfo,2,FALSE)-VLOOKUP(C56,SeedInfo,2,FALSE),0))) -> #REF! | E56: 50 | F56: {=_xlfn.XLOOKUP(G56,Teams[[#All],[Team]],Teams[[#All],[Seed]],0,0,1)} -> 6 | G56: Brigham Young | H56: vs | I56: Saint Mary's (CA) | J56: {=_xlfn.XLOOKUP(I56,Teams[[#All],[Team]],Teams[[#All],[Seed]],0,0,1)} -> 7 | K56: =_xlfn.XLOOKUP(G56,Teams!$C:$C,Teams!$E:$E,,0,1) -> #VALUE! | L56: 0.44 | M56: =_xlfn.XLOOKUP(I56,Teams!$C:$C,Teams!$E:$E,,0,1) -> #VALUE! | N56: 0.56 | O56: =IF(L56>N56,G56,I56) -> Saint Mary's (CA) | P56: =_xlfn.XLOOKUP(O56,Teams!$C:$C,Teams!$E:$E,,0,1) -> #VALUE! | Q56: Brigham Young: 219 - 282 :Saint Mary's (CA) | R56: =IF( O56=G56, IF(F56>J56,TRUE,FALSE), IF(J56>F56,TRUE,FALSE)) -> TRUE
A57: =G57 -> Florida | B57: =I57 -> Grand Canyon | C57: =IF(O57="","",IF(A57=O57,B57,A57)) -> Grand Canyon | D57: =IF(SeedType=1,0,IF(SeedType=2,VLOOKUP(O57,SeedInfo,2,FALSE)*3,MAX(VLOOKUP(O57,SeedInfo,2,FALSE)-VLOOKUP(C57,SeedInfo,2,FALSE),0))) -> #REF! | E57: 51 | F57: {=_xlfn.XLOOKUP(G57,Teams[[#All],[Team]],Teams[[#All],[Seed]],0,0,1)} -> 1 | G57: Florida | H57: vs | I57: Grand Canyon | J57: {=_xlfn.XLOOKUP(I57,Teams[[#All],[Team]],Teams[[#All],[Seed]],0,0,1)} -> 13 | K57: =_xlfn.XLOOKUP(G57,Teams!$C:$C,Teams!$E:$E,,0,1) -> #VALUE! | L57: 0.9 | M57: =_xlfn.XLOOKUP(I57,Teams!$C:$C,Teams!$E:$E,,0,1) -> #VALUE! | N57: 0.1 | O57: =IF(L57>N57,G57,I57) -> Florida | P57: =_xlfn.XLOOKUP(O57,Teams!$C:$C,Teams!$E:$E,,0,1) -> #VALUE! | Q57: Florida: 451 - 50 :Grand Canyon | R57: =IF( O57=G57, IF(F57>J57,TRUE,FALSE), IF(J57>F57,TRUE,FALSE)) -> FALSE
A58: =G58 -> Texas Tech | B58: =I58 -> St. John's (NY) | C58: =IF(O58="","",IF(A58=O58,B58,A58)) -> St. John's (NY) | D58: =IF(SeedType=1,0,IF(SeedType=2,VLOOKUP(O58,SeedInfo,2,FALSE)*3,MAX(VLOOKUP(O58,SeedInfo,2,FALSE)-VLOOKUP(C58,SeedInfo,2,FALSE),0))) -> #REF! | E58: 52 | F58: {=_xlfn.XLOOKUP(G58,Teams[[#All],[Team]],Teams[[#All],[Seed]],0,0,1)} -> 3 | G58: Texas Tech | H58: vs | I58: St. John's (NY) | J58: {=_xlfn.XLOOKUP(I58,Teams[[#All],[Team]],Teams[[#All],[Seed]],0,0,1)} -> 2 | K58: =_xlfn.XLOOKUP(G58,Teams!$C:$C,Teams!$E:$E,,0,1) -> #VALUE! | L58: 0.72 | M58: =_xlfn.XLOOKUP(I58,Teams!$C:$C,Teams!$E:$E,,0,1) -> #VALUE! | N58: 0.28 | O58: =IF(L58>N58,G58,I58) -> Texas Tech | P58: =_xlfn.XLOOKUP(O58,Teams!$C:$C,Teams!$E:$E,,0,1) -> #VALUE! | Q58: Texas Tech: 360 - 141 :St. John's (NY) | R58: =IF( O58=G58, IF(F58>J58,TRUE,FALSE), IF(J58>F58,TRUE,FALSE)) -> TRUE
A59: =G59 -> Auburn | B59: =I59 -> Michigan | C59: =IF(O59="","",IF(A59=O59,B59,A59)) -> Auburn | D59: =IF(SeedType=1,0,IF(SeedType=2,VLOOKUP(O59,SeedInfo,2,FALSE)*3,MAX(VLOOKUP(O59,SeedInfo,2,FALSE)-VLOOKUP(C59,SeedInfo,2,FALSE),0))) -> #REF! | E59: 53 | F59: {=_xlfn.XLOOKUP(G59,Teams[[#All],[Team]],Teams[[#All],[Seed]],0,0,1)} -> 1 | G59: Auburn | H59: vs | I59: Michigan | J59: {=_xlfn.XLOOKUP(I59,Teams[[#All],[Team]],Teams[[#All],[Seed]],0,0,1)} -> 5 | K59: =_xlfn.XLOOKUP(G59,Teams!$C:$C,Teams!$E:$E,,0,1) -> #VALUE! | L59: 0.21 | M59: =_xlfn.XLOOKUP(I59,Teams!$C:$C,Teams!$E:$E,,0,1) -> #VALUE! | N59: 0.79 | O59: =IF(L59>N59,G59,I59) -> Michigan | P59: =_xlfn.XLOOKUP(O59,Teams!$C:$C,Teams!$E:$E,,0,1) -> #VALUE! | Q59: Auburn: 104 - 397 :Michigan | R59: =IF( O59=G59, IF(F59>J59,TRUE,FALSE), IF(J59>F59,TRUE,FALSE)) -> TRUE
A60: =G60 -> North Carolina | B60: =I60 -> New Mexico | C60: =IF(O60="","",IF(A60=O60,B60,A60)) -> New Mexico | D60: =IF(SeedType=1,0,IF(SeedType=2,VLOOKUP(O60,SeedInfo,2,FALSE)*3,MAX(VLOOKUP(O60,SeedInfo,2,FALSE)-VLOOKUP(C60,SeedInfo,2,FALSE),0))) -> #REF! | E60: 54 | F60: {=_xlfn.XLOOKUP(G60,Teams[[#All],[Team]],Teams[[#All],[Seed]],0,0,1)} -> 11 | G60: North Carolina | H60: vs | I60: New Mexico | J60: {=_xlfn.XLOOKUP(I60,Teams[[#All],[Team]],Teams[[#All],[Seed]],0,0,1)} -> 10 | K60: =_xlfn.XLOOKUP(G60,Teams!$C:$C,Teams!$E:$E,,0,1) -> #VALUE! | L60: 0.72 | M60: =_xlfn.XLOOKUP(I60,Teams!$C:$C,Teams!$E:$E,,0,1) -> #VALUE! | N60: 0.28 | O60: =IF(L60>N60,G60,I60) -> North Carolina | P60: =_xlfn.XLOOKUP(O60,Teams!$C:$C,Teams!$E:$E,,0,1) -> #VALUE! | Q60: North Carolina: 363 - 138 :New Mexico | R60: =IF( O60=G60, IF(F60>J60,TRUE,FALSE), IF(J60>F60,TRUE,FALSE)) -> TRUE
A61: =G61 -> Gonzaga | B61: =I61 -> High Point | C61: =IF(O61="","",IF(A61=O61,B61,A61)) -> High Point | D61: =IF(SeedType=1,0,IF(SeedType=2,VLOOKUP(O61,SeedInfo,2,FALSE)*3,MAX(VLOOKUP(O61,SeedInfo,2,FALSE)-VLOOKUP(C61,SeedInfo,2,FALSE),0))) -> #REF! | E61: 55 | F61: {=_xlfn.XLOOKUP(G61,Teams[[#All],[Team]],Teams[[#All],[Seed]],0,0,1)} -> 8 | G61: Gonzaga | H61: vs | I61: High Point | J61: {=_xlfn.XLOOKUP(I61,Teams[[#All],[Team]],Teams[[#All],[Seed]],0,0,1)} -> 13 | K61: =_xlfn.XLOOKUP(G61,Teams!$C:$C,Teams!$E:$E,,0,1) -> #VALUE! | L61: 0.76 | M61: =_xlfn.XLOOKUP(I61,Teams!$C:$C,Teams!$E:$E,,0,1) -> #VALUE! | N61: 0.24 | O61: =IF(L61>N61,G61,I61) -> Gonzaga | P61: =_xlfn.XLOOKUP(O61,Teams!$C:$C,Teams!$E:$E,,0,1) -> #VALUE! | Q61: Gonzaga: 382 - 119 :High Point | R61: =IF( O61=G61, IF(F61>J61,TRUE,FALSE), IF(J61>F61,TRUE,FALSE)) -> FALSE
A62: =G62 -> Illinois | B62: =I62 -> Tennessee | C62: =IF(O62="","",IF(A62=O62,B62,A62)) -> Tennessee | D62: =IF(SeedType=1,0,IF(SeedType=2,VLOOKUP(O62,SeedInfo,2,FALSE)*3,MAX(VLOOKUP(O62,SeedInfo,2,FALSE)-VLOOKUP(C62,SeedInfo,2,FALSE),0))) -> #REF! | E62: 56 | F62: {=_xlfn.XLOOKUP(G62,Teams[[#All],[Team]],Teams[[#All],[Seed]],0,0,1)} -> 6 | G62: Illinois | H62: vs | I62: Tennessee | J62: {=_xlfn.XLOOKUP(I62,Teams[[#All],[Team]],Teams[[#All],[Seed]],0,0,1)} -> 2 | K62: =_xlfn.XLOOKUP(G62,Teams!$C:$C,Teams!$E:$E,,0,1) -> #VALUE! | L62: 0.7 | M62: =_xlfn.XLOOKUP(I62,Teams!$C:$C,Teams!$E:$E,,0,1) -> #VALUE! | N62: 0.3 | O62: =IF(L62>N62,G62,I62) -> Illinois | P62: =_xlfn.XLOOKUP(O62,Teams!$C:$C,Teams!$E:$E,,0,1) -> #VALUE! | Q62: Illinois: 352 - 149 :Tennessee | R62: =IF( O62=G62, IF(F62>J62,TRUE,FALSE), IF(J62>F62,TRUE,FALSE)) -> TRUE
E63: Game # | F63: =Bracket!L2 -> Elite 8 | O63: Winner
...

Sheet Bracket
B1: 2026 NCAA Basketball Tournament Bracket
C2: First Round | F2: Second Round | I2: Sweet 16 | L2: Elite 8 | O2: Final Four | S2: Championship | AA2: Final Four | AD2: Elite 8 | AG2: Sweet 16 | AJ2: =F2 -> Second Round | AM2: =C2 -> First Round | AU2: checkbox
AU3: x
B5: 1 | C5: =Games!G5 -> Duke | D5: =_xlfn.XLOOKUP(C5,Teams!$C:$C,Teams!$E:$E,,0,1) -> #VALUE! | E5: =Games!L5 -> 0.98 | F5: =Games!O5 -> Duke | G5: =_xlfn.XLOOKUP(F5,Teams!$C:$C,Teams!$E:$E,,0,1) -> #VALUE! | H5: =Games!L38 -> 0.85 | AH5: =Games!L46 -> 0.5 | AI5: =_xlfn.XLOOKUP(AJ5,Teams!$C:$C,Teams!$E:$E,,0,1) -> #VALUE! | AJ5: =Games!O21 -> Auburn | AK5: =Games!L21 -> 0.96 | AL5: =_xlfn.XLOOKUP(AM5,Teams!$C:$C,Teams!$E:$E,,0,1) -> #VALUE! | AM5: =Games!G21 -> Auburn | AN5: 1 | AU5: =IF(AP29="x",TRUE,FALSE) -> TRUE
A6: =IF($AU$5=TRUE,1,"") -> 1 | AO6: =IF($AU$5=TRUE,A66+1,"") -> 17
B7: 16 | C7: =Games!I5 -> Mount St. Mary's | D7: =_xlfn.XLOOKUP(C7,Teams!$C:$C,Teams!$E:$E,,0,1) -> #VALUE! | E7: =Games!N5 -> 0.02 | F7: =IF($AU$5=TRUE,AO66+1,"") -> 33 | I7: =Games!O38 -> Duke | J7: =_xlfn.XLOOKUP(I7,Teams!$C:$C,Teams!$E:$E,,0,1) -> #VALUE! | K7: =Games!L55 -> 0.78 | AE7: =Games!L59 -> 0.21 | AF7: =_xlfn.XLOOKUP(AG7,Teams!$C:$C,Teams!$E:$E,,0,1) -> #VALUE! | AG7: =Games!O46 -> Louisville | AJ7: =IF($AU$5=TRUE,F63+1,"") -> 41 | AK7: =Games!N21 -> 0.04 | AL7: =_xlfn.XLOOKUP(AM7,Teams!$C:$C,Teams!$E:$E,,0,1) -> #VALUE! | AM7: =Games!I21 -> Alabama State | AN7: 16
B9: 8 | C9: =Games!G6 -> Mississippi State | D9: =_xlfn.XLOOKUP(C9,Teams!$C:$C,Teams!$E:$E,,0,1) -> #VALUE! | E9: =Games!L6 -> 0.34 | F9: =Games!O6 -> Baylor | G9: =_xlfn.XLOOKUP(F9,Teams!$C:$C,Teams!$E:$E,,0,1) -> #VALUE! | H9: =Games!N38 -> 0.15 | AH9: =Games!N46 -> 0.5 | AI9: =_xlfn.XLOOKUP(AJ9,Teams!$C:$C,Teams!$E:$E,,0,1) -> #VALUE! | AJ9: =Games!O22 -> Louisville | AK9: =Games!L22 -> 0.8 | AL9: =_xlfn.XLOOKUP(AM9,Teams!$C:$C,Teams!$E:$E,,0,1) -> #VALUE! | AM9: =Games!G22 -> Louisville | AN9: 8
A10: =IF($AU$5=TRUE,A6+1,"") -> 2 | AO10: =IF($AU$5=TRUE,AO6+1,"") -> 18
B11: 9 | C11: =Games!I6 -> Baylor | D11: =_xlfn.XLOOKUP(C11,Teams!$C:$C,Teams!$E:$E,,0,1) -> #VALUE! | E11: =Games!N6 -> 0.66 | I11: =IF($AU$5=TRUE,AJ63+1,"") -> 49 | L11: =Games!O55 -> Duke | M11: =_xlfn.XLOOKUP(L11,Teams!$C:$C,Teams!$E:$E,,0,1) -> #VALUE! | N11: =Games!L64 -> 0.6 | T11: =_xlfn.XLOOKUP(S32,Teams!$C:$C,Teams!$E:$E,,0,1) -> #VALUE! | AB11: =Games!L66 -> 0.55 | AC11: =_xlfn.XLOOKUP(AD11,Teams!$C:$C,Teams!$E:$E,,0,1) -> #VALUE! | AD11: =Games!O59 -> Michigan | AG11: =IF($AU$5=TRUE,I59+1,"") -> 53 | AK11: =Games!N22 -> 0.2 | AL11: =_xlfn.XLOOKUP(AM11,Teams!$C:$C,Teams!$E:$E,,0,1) -> #VALUE! | AM11: =Games!I22 -> Creighton | AN11: 9
B13: 5 | C13: =Games!G7 -> Oregon | D13: =_xlfn.XLOOKUP(C13,Teams!$C:$C,Teams!$E:$E,,0,1) -> #VALUE! | E13: =Games!L7 -> 0.12 | F13: =Games!O7 -> Liberty | G13: =_xlfn.XLOOKUP(F13,Teams!$C:$C,Teams!$E:$E,,0,1) -> #VALUE! | H13: =Games!L39 -> 0.46 | AH13: =Games!L47 -> 0.77 | AI13: =_xlfn.XLOOKUP(AJ13,Teams!$C:$C,Teams!$E:$E,,0,1) -> #VALUE! | AJ13: =Games!O23 -> Michigan | AK13: =Games!L23 -> 0.91 | AL13: =_xlfn.XLOOKUP(AM13,Teams!$C:$C,Teams!$E:$E,,0,1) -> #VALUE! | AM13: =Games!G23 -> Michigan | AN13: 5
A14: =IF($AU$5=TRUE,A10+1,"") -> 3 | AO14: =IF($AU$5=TRUE,AO10+1,"") -> 19
B15: 12 | C15: =Games!I7 -> Liberty | D15: =_xlfn.XLOOKUP(C15,Teams!$C:$C,Teams!$E:$E,,0,1) -> #VALUE! | E15: =Games!N7 -> 0.88 | F15: =IF($AU$5=TRUE,F7+1,"") -> 34 | I15: =Games!O39 -> Akron | J15: =_xlfn.XLOOKUP(I15,Teams!$C:$C,Teams!$E:$E,,0,1) -> #VALUE! | K15: =Games!N55 -> 0.22 | AE15: =Games!N59 -> 0.79 | AF15: =_xlfn.XLOOKUP(AG15,Teams!$C:$C,Teams!$E:$E,,0,1) -> #VALUE! | AG15: =Games!O47 -> Michigan | AJ15: =IF($AU$5=TRUE,AJ7+1,"") -> 42 | AK15: =Games!N23 -> 0.09 | AL15: =_xlfn.XLOOKUP(AM15,Teams!$C:$C,Teams!$E:$E,,0,1) -> #VALUE! | AM15: =Games!I23 -> UC San Diego | AN15: 12
B17: 4 | C17: =Games!G8 -> Arizona | D17: =_xlfn.XLOOKUP(C17,Teams!$C:$C,Teams!$E:$E,,0,1) -> #VALUE! | E17: =Games!L8 -> 0.12 | F17: =Games!O8 -> Akron | G17: =_xlfn.XLOOKUP(F17,Teams!$C:$C,Teams!$E:$E,,0,1) -> #VALUE! | H17: =Games!N39 -> 0.54 | AH17: =Games!N47 -> 0.23 | AI17: =_xlfn.XLOOKUP(AJ17,Teams!$C:$C,Teams!$E:$E,,0,1) -> #VALUE! | AJ17: =Games!O24 -> Yale | AK17: =Games!L24 -> 0.3 | AL17: =_xlfn.XLOOKUP(AM17,Teams!$C:$C,Teams!$E:$E,,0,1) -> #VALUE! | AM17: =Games!G24 -> Texas A&M | AN17: 4
A18: =IF($AU$5=TRUE,A14+1,"") -> 4 | AO18: =IF($AU$5=TRUE,AO14+1,"") -> 20
B19: 13 | C19: =Games!I8 -> Akron | D19: =_xlfn.XLOOKUP(C19,Teams!$C:$C,Teams!$E:$E,,0,1) -> #VALUE! | E19: =Games!N8 -> 0.88 | K19: South | O19: =Games!O64 -> Duke | P19: =_xlfn.XLOOKUP(O19,Teams!$C:$C,Teams!$E:$E,,0,1) -> #VALUE! | Q19: =Games!L69 -> 0.42 | Y19: =Games!L70 -> 0.54 | Z19: =_xlfn.XLOOKUP(AA19,Teams!$C:$C,Teams!$E:$E,,0,1) -> #VALUE! | AA19: =Games!O66 -> Michigan | AD19: East | AK19: =Games!N24 -> 0.7 | AL19: =_xlfn.XLOOKUP(AM19,Teams!$C:$C,Teams!$E:$E,,0,1) -> #VALUE! | AM19: =Games!I24 -> Yale | AN19: 13
A21: =IF($AU$5=TRUE,A18+1,"") -> 5 | B21: 6 | C21: =Games!G9 -> Brigham Young | D21: =_xlfn.XLOOKUP(C21,Teams!$C:$C,Teams!$E:$E,,0,1) -> #VALUE! | E21: =Games!L9 -> 0.72 | F21: =Games!O9 -> Brigham Young | G21: =_xlfn.XLOOKUP(F21,Teams!$C:$C,Teams!$E:$E,,0,1) -> #VALUE! | H21: =Games!L40 -> 0.58 | L21: =IF($AU$5=TRUE,AG59+1,"") -> 57 | AD21: =IF($AU$5=TRUE,L53+1,"") -> 59 | AH21: =Games!L48 -> 0.55 | AI21: =_xlfn.XLOOKUP(AJ21,Teams!$C:$C,Teams!$E:$E,,0,1) -> #VALUE! | AJ21: =Games!O25 -> North Carolina | AK21: =Games!L25 -> 0.08 | AL21: =_xlfn.XLOOKUP(AM21,Teams!$C:$C,Teams!$E:$E,,0,1) -> #VALUE! | AM21: =Games!G25 -> Mississippi | AN21: 6
AO22: =IF($AU$5=TRUE,AO18+1,"") -> 21
B23: 11 | C23: =Games!I9 -> Virginia Commonwealth | D23: =_xlfn.XLOOKUP(C23,Teams!$C:$C,Teams!$E:$E,,0,1) -> #VALUE! | E23: =Games!N9 -> 0.28 | F23: =IF($AU$5=TRUE,F15+1,"") -> 35 | I23: =Games!O40 -> Brigham Young | J23: =_xlfn.XLOOKUP(I23,Teams!$C:$C,Teams!$E:$E,,0,1) -> #VALUE! | K23: =Games!L56 -> 0.44 | AE23: =Games!L60 -> 0.72 | AF23: =_xlfn.XLOOKUP(AG23,Teams!$C:$C,Teams!$E:$E,,0,1) -> #VALUE! | AG23: =Games!O48 -> North Carolina | AJ23: =IF($AU$5=TRUE,AJ15+1,"") -> 43 | AK23: =Games!N25 -> 0.92 | AL23: =_xlfn.XLOOKUP(AM23,Teams!$C:$C,Teams!$E:$E,,0,1) -> #VALUE! | AM23: =Games!I25 -> North Carolina | AN23: 11
B25: 3 | C25: =Games!G10 -> Wisconsin | D25: =_xlfn.XLOOKUP(C25,Teams!$C:$C,Teams!$E:$E,,0,1) -> #VALUE! | E25: =Games!L10 -> 0.94 | F25: =Games!O10 -> Wisconsin | G25: =_xlfn.XLOOKUP(F25,Teams!$C:$C,Teams!$E:$E,,0,1) -> #VALUE! | H25: =Games!N40 -> 0.42 | AH25: =Games!N48 -> 0.45 | AI25: =_xlfn.XLOOKUP(AJ25,Teams!$C:$C,Teams!$E:$E,,0,1) -> #VALUE! | AJ25: =Games!O26 -> Iowa State | AK25: =Games!L26 -> 0.95 | AL25: =_xlfn.XLOOKUP(AM25,Teams!$C:$C,Teams!$E:$E,,0,1) -> #VALUE! | AM25: =Games!G26 -> Iowa State | AN25: 3
A26: =IF($AU$5=TRUE,A21+1,"") -> 6 | AO26: =IF($AU$5=TRUE,AO22+1,"") -> 22
B27: 14 | C27: =Games!I10 -> Montana | D27: =_xlfn.XLOOKUP(C27,Teams!$C:$C,Teams!$E:$E,,0,1) -> #VALUE! | E27: =Games!N10 -> 0.06 | I27: =IF($AU$5=TRUE,I11+1,"") -> 50 | L27: =Games!O56 -> Saint Mary's (CA) | M27: =_xlfn.XLOOKUP(L27,Teams!$C:$C,Teams!$E:$E,,0,1) -> #VALUE! | N27: =Games!N64 -> 0.4 | R27: =Games!O69 -> Florida | U27: =_xlfn.XLOOKUP(R27,Teams!$C:$C,Teams!$E:$E,,0,1) -> #VALUE! | V27: =Games!L72 -> 0.72 | AB27: =Games!N66 -> 0.45 | AC27: =_xlfn.XLOOKUP(AD27,Teams!$C:$C,Teams!$E:$E,,0,1) -> #VALUE! | AD27: =Games!O60 -> North Carolina | AG27: =IF($AU$5=TRUE,AG11+1,"") -> 54 | AK27: =Games!N26 -> 0.05 | AL27: =_xlfn.XLOOKUP(AM27,Teams!$C:$C,Teams!$E:$E,,0,1) -> #VALUE! | AM27: =Games!I26 -> Lipscomb | AN27: 14
B29: 7 | C29: =Games!G11 -> Saint Mary's (CA) | D29: =_xlfn.XLOOKUP(C29,Teams!$C:$C,Teams!$E:$E,,0,1) -> #VALUE! | E29: =Games!L11 -> 0.71 | F29: =Games!O11 -> Saint Mary's (CA) | G29: =_xlfn.XLOOKUP(F29,Teams!$C:$C,Teams!$E:$E,,0,1) -> #VALUE! | H29: =Games!L41 -> 0.51 | AH29: =Games!L49 -> 0.56 | AI29: =_xlfn.XLOOKUP(AJ29,Teams!$C:$C,Teams!$E:$E,,0,1) -> #VALUE! | AJ29: =Games!O27 -> New Mexico | AK29: =Games!L27 -> 0.19 | AL29: =_xlfn.XLOOKUP(AM29,Teams!$C:$C,Teams!$E:$E,,0,1) -> #VALUE! | AM29: =Games!G27 -> Marquette | AN29: 7 | AP29: x | AQ29: Show Game Numbers
A30: =IF($AU$5=TRUE,A26+1,"") -> 7 | AO30: =IF($AU$5=TRUE,AO26+1,"") -> 23
B31: 10 | C31: =Games!I14 -> Oklahoma | D31: =_xlfn.XLOOKUP(C31,Teams!$C:$C,Teams!$E:$E,,0,1) -> #VALUE! | E31: =Games!N11 -> 0.29 | F31: =IF($AU$5=TRUE,F23+1,"") -> 36 | I31: =Games!O41 -> Saint Mary's (CA) | J31: =_xlfn.XLOOKUP(I31,Teams!$C:$C,Teams!$E:$E,,0,1) -> #VALUE! | K31: =Games!N56 -> 0.56 | S31: National Champion | AE31: =Games!N60 -> 0.28 | AF31: =_xlfn.XLOOKUP(AG31,Teams!$C:$C,Teams!$E:$E,,0,1) -> #VALUE! | AG31: =Games!O49 -> New Mexico | AJ31: =IF($AU$5=TRUE,AJ23+1,"") -> 44 | AK31: =Games!N27 -> 0.81 | AL31: =_xlfn.XLOOKUP(AM31,Teams!$C:$C,Teams!$E:$E,,0,1) -> #VALUE! | AM31: =Games!I27 -> New Mexico | AN31: 10
S32: =Games!O72 -> Florida
B33: 2 | C33: =Games!G12 -> Alabama | D33: =_xlfn.XLOOKUP(C33,Teams!$C:$C,Teams!$E:$E,,0,1) -> #VALUE! | E33: =Games!L12 -> 0.94 | F33: =Games!O12 -> Alabama | G33: =_xlfn.XLOOKUP(F33,Teams!$C:$C,Teams!$E:$E,,0,1) -> #VALUE! | H33: =Games!N41 -> 0.49 | AH33: =Games!N49 -> 0.44 | AI33: =_xlfn.XLOOKUP(AJ33,Teams!$C:$C,Teams!$E:$E,,0,1) -> #VALUE! | AJ33: =Games!O28 -> Michigan State | AK33: =Games!L28 -> 0.97 | AL33: =_xlfn.XLOOKUP(AM33,Teams!$C:$C,Teams!$E:$E,,0,1) -> #VALUE! | AM33: =Games!G28 -> Michigan State | AN33: 2
A34: =IF($AU$5=TRUE,A30+1,"") -> 8 | AO34: =IF($AU$5=TRUE,AO30+1,"") -> 24
B35: 15 | C35: =Games!I12 -> Robert Morris | D35: =_xlfn.XLOOKUP(C35,Teams!$C:$C,Teams!$E:$E,,0,1) -> #VALUE! | E35: =Games!N12 -> 0.06 | O35: =IF($AU$5=TRUE,AD53+1,"") -> 61 | T35: =IF($AU$5=TRUE,AA35+1,"") -> 63 | AA35: =IF($AU$5=TRUE,O35+1,"") -> 62 | AK35: =Games!N28 -> 0.03 | AL35: =_xlfn.XLOOKUP(AM35,Teams!$C:$C,Teams!$E:$E,,0,1) -> #VALUE! | AM35: =Games!I28 -> Bryant | AN35: 15
B37: 1 | C37: =Games!G13 -> Florida | D37: =_xlfn.XLOOKUP(C37,Teams!$C:$C,Teams!$E:$E,,0,1) -> #VALUE! | E37: =Games!L13 -> 1 | F37: =Games!O13 -> Florida | G37: =_xlfn.XLOOKUP(F37,Teams!$C:$C,Teams!$E:$E,,0,1) -> #VALUE! | H37: =Games!L42 -> 0.8 | AH37: =Games!L50 -> 0.44 | AI37: =_xlfn.XLOOKUP(AJ37,Teams!$C:$C,Teams!$E:$E,,0,1) -> #VALUE! | AJ37: =Games!O29 -> Houston | AK37: =Games!L29 -> 0.96 | AL37: =_xlfn.XLOOKUP(AM37,Teams!$C:$C,Teams!$E:$E,,0,1) -> #VALUE! | AM37: =Games!G29 -> Houston | AN37: 1
A38: =IF($AU$5=TRUE,A34+1,"") -> 9 | AO38: =IF($AU$5=TRUE,AO34+1,"") -> 25
B39: 16 | C39: =Games!I13 -> Norfolk State | D39: =_xlfn.XLOOKUP(C39,Teams!$C:$C,Teams!$E:$E,,0,1) -> #VALUE! | E39: =Games!N13 -> 0 | F39: =IF($AU$5=TRUE,F31+1,"") -> 37 | I39: =Games!O42 -> Florida | J39: =_xlfn.XLOOKUP(I39,Teams!$C:$C,Teams!$E:$E,,0,1) -> #VALUE! | K39: =Games!L57 -> 0.9 | T39: =Games!N72 -> 0.28 | U39: =_xlfn.XLOOKUP(V39,Teams!$C:$C,Teams!$E:$E,,0,1) -> #VALUE! | V39: =Games!O70 -> Michigan | AE39: =Games!L61 -> 0.76 | AF39: =_xlfn.XLOOKUP(AG39,Teams!$C:$C,Teams!$E:$E,,0,1) -> #VALUE! | AG39: =Games!O50 -> Gonzaga | AJ39: =IF($AU$5=TRUE,AJ31+1,"") -> 45 | AK39: =Games!N29 -> 0.04 | AL39: =_xlfn.XLOOKUP(AM39,Teams!$C:$C,Teams!$E:$E,,0,1) -> #VALUE! | AM39: =Games!I29 -> SIU Edwardsville | AN39: 16
B41: 8 | C41: =Games!G14 -> Connecticut | D41: =_xlfn.XLOOKUP(C41,Teams!$C:$C,Teams!$E:$E,,0,1) -> #VALUE! | E41: =Games!L14 -> 0.83 | F41: =Games!O14 -> Connecticut | G41: =_xlfn.XLOOKUP(F41,Teams!$C:$C,Teams!$E:$E,,0,1) -> #VALUE! | H41: =Games!N42 -> 0.2 | AH41: =Games!N50 -> 0.56 | AI41: =_xlfn.XLOOKUP(AJ41,Teams!$C:$C,Teams!$E:$E,,0,1) -> #VALUE! | AJ41: =Games!O30 -> Gonzaga | AK41: =Games!L30 -> 0.75 | AL41: =_xlfn.XLOOKUP(AM41,Teams!$C:$C,Teams!$E:$E,,0,1) -> #VALUE! | AM41: =Games!G30 -> Gonzaga | AN41: 8
A42: =IF($AU$5=TRUE,A38+1,"") -> 10 | AO42: =IF($AU$5=TRUE,AO38+1,"") -> 26
B43: 9 | C43: =Games!I14 -> Oklahoma | D43: =_xlfn.XLOOKUP(C43,Teams!$C:$C,Teams!$E:$E,,0,1) -> #VALUE! | E43: =Games!N14 -> 0.17 | I43: =IF($AU$5=TRUE,I27+1,"") -> 51 | L43: =Games!O57 -> Florida | M43: =_xlfn.XLOOKUP(L43,Teams!$C:$C,Teams!$E:$E,,0,1) -> #VALUE! | N43: =Games!L65 -> 0.54 | AB43: =Games!L67 -> 0.54 | AC43: =_xlfn.XLOOKUP(AD43,Teams!$C:$C,Teams!$E:$E,,0,1) -> #VALUE! | AD43: =Games!O61 -> Gonzaga | AG43: =IF($AU$5=TRUE,AG27+1,"") -> 55 | AK43: =Games!N30 -> 0.25 | AL43: =_xlfn.XLOOKUP(AM43,Teams!$C:$C,Teams!$E:$E,,0,1) -> #VALUE! | AM43: =Games!I30 -> Georgia | AN43: 9
B45: 5 | C45: =Games!G15 -> Memphis | D45: =_xlfn.XLOOKUP(C45,Teams!$C:$C,Teams!$E:$E,,0,1) -> #VALUE! | E45: =Games!L15 -> 0.31 | F45: =Games!O15 -> Colorado State | G45: =_xlfn.XLOOKUP(F45,Teams!$C:$C,Teams!$E:$E,,0,1) -> #VALUE! | H45: =Games!L43 -> 0.23 | AH45: =Games!L51 -> 0.38 | AI45: =_xlfn.XLOOKUP(AJ45,Teams!$C:$C,Teams!$E:$E,,0,1) -> #VALUE! | AJ45: =Games!O31 -> McNeese State | AK45: =Games!L31 -> 0.36 | AL45: =_xlfn.XLOOKUP(AM45,Teams!$C:$C,Teams!$E:$E,,0,1) -> #VALUE! | AM45: =Games!G31 -> Clemson | AN45: 5
A46: =IF($AU$5=TRUE,A42+1,"") -> 11 | AO46: =IF($AU$5=TRUE,AO42+1,"") -> 27
B47: 12 | C47: =Games!I15 -> Colorado State | D47: =_xlfn.XLOOKUP(C47,Teams!$C:$C,Teams!$E:$E,,0,1) -> #VALUE! | E47: =Games!N15 -> 0.69 | F47: =IF($AU$5=TRUE,F39+1,"") -> 38 | I47: =Games!O43 -> Grand Canyon | J47: =_xlfn.XLOOKUP(I47,Teams!$C:$C,Teams!$E:$E,,0,1) -> #VALUE! | K47: =Games!N57 -> 0.1 | AE47: =Games!N61 -> 0.24 | AF47: =_xlfn.XLOOKUP(AG47,Teams!$C:$C,Teams!$E:$E,,0,1) -> #VALUE! | AG47: =Games!O51 -> High Point | AJ47: =IF($AU$5=TRUE,AJ39+1,"") -> 46 | AK47: =Games!N31 -> 0.64 | AL47: =_xlfn.XLOOKUP(AM47,Teams!$C:$C,Teams!$E:$E,,0,1) -> #VALUE! | AM47: =Games!I31 -> McNeese State | AN47: 12
B49: 4 | C49: =Games!G16 -> Maryland | D49: =_xlfn.XLOOKUP(C49,Teams!$C:$C,Teams!$E:$E,,0,1) -> #VALUE! | E49: =Games!L16 -> 0.22 | F49: =Games!O16 -> Grand Canyon | G49: =_xlfn.XLOOKUP(F49,Teams!$C:$C,Teams!$E:$E,,0,1) -> #VALUE! | H49: =Games!N43 -> 0.77 | AH49: =Games!N51 -> 0.62 | AI49: =_xlfn.XLOOKUP(AJ49,Teams!$C:$C,Teams!$E:$E,,0,1) -> #VALUE! | AJ49: =Games!O32 -> High Point | AK49: =Games!L32 -> 0.32 | AL49: =_xlfn.XLOOKUP(AM49,Teams!$C:$C,Teams!$E:$E,,0,1) -> #VALUE! | AM49: =Games!G32 -> Purdue | AN49: 4
A50: =IF($AU$5=TRUE,A46+1,"") -> 12 | AO50: =IF($AU$5=TRUE,AO46+1,"") -> 28
B51: 13 | C51: =Games!I16 -> Grand Canyon | D51: =_xlfn.XLOOKUP(C51,Teams!$C:$C,Teams!$E:$E,,0,1) -> #VALUE! | E51: =Games!N16 -> 0.78 | K51: West | O51: =Games!O65 -> Florida | P51: =_xlfn.XLOOKUP(O51,Teams!$C:$C,Teams!$E:$E,,0,1) -> #VALUE! | Q51: =Games!N69 -> 0.58 | Y51: =Games!N70 -> 0.46 | Z51: =_xlfn.XLOOKUP(AA51,Teams!$C:$C,Teams!$E:$E,,0,1) -> #VALUE! | AA51: =Games!O67 -> Gonzaga | AD51: Midwest | AK51: =Games!N32 -> 0.68 | AL51: =_xlfn.XLOOKUP(AM51,Teams!$C:$C,Teams!$E:$E,,0,1) -> #VALUE! | AM51: =Games!I32 -> High Point | AN51: 13
...
